Traceback (most recent call last):
  File "/home/chiar/anaconda3/envs/mldl/lib/python3.7/site-packages/wandb/sdk/wandb_config.py", line 162, in __getattr__
    return self.__getitem__(key)
  File "/home/chiar/anaconda3/envs/mldl/lib/python3.7/site-packages/wandb/sdk/wandb_config.py", line 130, in __getitem__
    return self._items[key]
KeyError: 'learning_rate'
The above exception was the direct cause of the following exception:
Traceback (most recent call last):
  File "train_sb3_tuning.py", line 117, in <module>
    main()
  File "train_sb3_tuning.py", line 109, in main
    wandb.agent(sweep_id=sweep_id, function = train_test(train_env, test_env))
  File "train_sb3_tuning.py", line 55, in train_test
    model=PPO(policy='MlpPolicy', env=train_env, learning_rate=config.learning_rate, n_steps=config.n_steps, batch_size=config.batch_size, n_epochs=config.n_epochs, seed=args.seed)
  File "/home/chiar/anaconda3/envs/mldl/lib/python3.7/site-packages/wandb/sdk/wandb_config.py", line 166, in __getattr__
    ) from ke
AttributeError: <class 'wandb.sdk.wandb_config.Config'> object has no attribute 'learning_rate'